<?xml version="1.0"?>
<robot xmlns:xacro="http://www.ros.org/wiki/xacro"  name="RobuROC">

    <!-- This is RobuROC model for rviz visualisation -->
    <!-- Model visualisation is made of stl files and collison is made of simple shapes box and cylinders-->



    <!-- Initial link is empty link called base_link -->
    <link name="base_link"></link>

    <!-- ##############################################  -->
    <!--                Chassis Link                     -->
    <!-- ##############################################  -->

    <!-- Chassis joint has been off seted in z axis and set to fixed-->
    <joint name="chassis_joint" type="fixed">
        <parent link="base_link"/>
        <child link="chassis_link"/>        
    </joint>

    <link name="chassis_link">
        <visual>
            <origin xyz="${chassis_vis_origin}" rpy="${rot_90} 0 ${rot_90}"/>
            <geometry>
                <mesh filename="file://$(find RobuROC_sim)/meshes/chassis.STL" scale="${scale}"/>
            </geometry>
            <material name="grey" />
        </visual>
        <collision>
            <origin xyz="${chassis_col_origin}" rpy="0 0 0"/>
            <geometry>
                <box size="${box_x} ${box_y} ${box_z}" />
            </geometry>
        </collision>
       <xacro:inertial_box mass="${box_m}" x="${box_x}" y="${box_y}" z="${box_z}">
            <origin xyz="${chassis_col_origin}" rpy="0 0 0"/>
        </xacro:inertial_box>
    </link>

    <!-- ##############################################  -->
    <!--                WHEEL 1  +x +y                   -->
    <!-- ##############################################  -->

    <joint name="wheel_1_joint" type="continuous">
        <origin xyz="${wheel_1_origin}" rpy="${-rot_90} 0 0"/>
        <parent link="base_link"/>
        <child link="wheel_1_link"/>        
        <axis xyz="0 0 1" />
        <limit effort="1000" velocity="${max_vel}"/>
        <dynamics damping="1.0" friction="1.0"/>
    </joint>

    <link name="wheel_1_link">
        <visual>
            <origin xyz="0 0 0" rpy="0 ${rot_90} 0"/>
            <geometry>
                <mesh filename="file://$(find RobuROC_sim)/meshes/wheel.STL" scale = "${scale}"/>
            </geometry>
            <material name="black" />
        </visual>
        <collision>
            <origin xyz="0 0 0" rpy="0 0 0"/>
            <geometry>
                <cylinder length="${cyl_l}" radius="${cyl_r}" />
            </geometry>
        </collision>
        <xacro:inertial_cylinder mass="${cyl_m}" length="${cyl_l}" radius="${cyl_r}">
            <origin xyz="0 0 0" rpy="0 0 0"/>
        </xacro:inertial_cylinder>
    </link>

    <!-- ##############################################  -->
    <!--                WHEEL 2  +x -y                   -->
    <!-- ##############################################  -->

    <joint name="wheel_2_joint" type="continuous">
        <origin xyz="${wheel_2_origin}" rpy="${-rot_90} 0 0"/>
        <parent link="base_link"/>
        <child link="wheel_2_link"/>        
        <axis xyz="0 0 1" />
        <limit effort="1000" velocity="${max_vel}"/>
        <dynamics damping="1.0" friction="1.0"/>
    </joint>

    <link name="wheel_2_link">
        <visual>
            <origin xyz="0 0 0" rpy="0 ${rot_90} 0"/>
            <geometry>
                <mesh filename="file://$(find RobuROC_sim)/meshes/wheel.STL" scale = "${scale}"/>
            </geometry>
            <material name="black" />
        </visual>
        <collision>
            <origin xyz="0 0 0" rpy="0 0 0"/>
            <geometry>
                <cylinder length="${cyl_l}" radius="${cyl_r}" />
            </geometry>
        </collision>
        <xacro:inertial_cylinder mass="${cyl_m}" length="${cyl_l}" radius="${cyl_r}">
            <origin xyz="0 0 0" rpy="0 0 0"/>
        </xacro:inertial_cylinder>
    </link>

    <!-- ##############################################  -->
    <!--                WHEEL 3  -x -y                   -->
    <!-- ##############################################  -->

    <joint name="wheel_3_joint" type="continuous">
        <origin xyz="${wheel_3_origin}" rpy="${-rot_90} 0 0"/>
        <parent link="base_link"/>
        <child link="wheel_3_link"/>        
        <axis xyz="0 0 1" />
        <limit effort="1000" velocity="${max_vel}"/>
        <dynamics damping="1.0" friction="1.0"/>
    </joint>

    <link name="wheel_3_link">
        <visual>
            <origin xyz="0 0 0" rpy="0 ${rot_90} 0"/>
            <geometry>
                <mesh filename="file://$(find RobuROC_sim)/meshes/wheel.STL" scale = "${scale}"/>
            </geometry>
            <material name="black" />
        </visual>
        <collision>
            <origin xyz="0 0 0" rpy="0 0 0"/>
            <geometry>
                <cylinder length="${cyl_l}" radius="${cyl_r}" />
            </geometry>
        </collision>
        <xacro:inertial_cylinder mass="${cyl_m}" length="${cyl_l}" radius="${cyl_r}">
            <origin xyz="0 0 0" rpy="0 0 0"/>
        </xacro:inertial_cylinder>
    </link>

    <!-- ##############################################  -->
    <!--                WHEEL 4  -x +y                   -->
    <!-- ##############################################  -->

    <joint name="wheel_4_joint" type="continuous">
        <origin xyz="${wheel_4_origin}" rpy="${-rot_90} 0 0"/>
        <parent link="base_link"/>
        <child link="wheel_4_link"/>        
        <axis xyz="0 0 1" />
        <limit effort="1000" velocity="${max_vel}"/>
        <dynamics damping="1.0" friction="1.0"/>
    </joint>

    <link name="wheel_4_link">
        <visual>
            <origin xyz="0 0 0" rpy="0 ${rot_90} 0"/>
            <geometry>
                <mesh filename="file://$(find RobuROC_sim)/meshes/wheel.STL" scale = "${scale}"/>
            </geometry>
            <material name="black" />
        </visual>
        <collision>
            <origin xyz="0 0 0" rpy="0 0 0"/>
            <geometry>
                <cylinder length="${cyl_l}" radius="${cyl_r}" />
            </geometry>
        </collision>
        <xacro:inertial_cylinder mass="${cyl_m}" length="${cyl_l}" radius="${cyl_r}">
            <origin xyz="0 0 0" rpy="0 0 0"/>
        </xacro:inertial_cylinder>
    </link>


</robot>