<?xml version="1.0"?>
<robot xmlns:xacro="http://www.ros.org/wiki/xacro"  name="robot">

    <!-- This will inculde all function for all parts-->
    <xacro:include filename="example_include.xacro" />
    
    <!--Paraneters-->
    <xacro:property name="box_x" value="0.54" />
    <xacro:property name="box_y" value="0.925" />
    <xacro:property name="box_z" value="0.304" />
    <xacro:property name="box_m" value="100" />
    <xacro:property name="box_off_z" value="0.484" />
    <xacro:property name="cyl_l" value="0.1" />
    <xacro:property name="cyl_r" value="0.28" />
    <xacro:property name="cyl_m" value="10" />
    <xacro:property name="cyl_off_x" value="0.3068" />
    <xacro:property name="cyk_off_y" value="0.3425" />
    <xacro:property name="cyk_off_z" value="0.0.204" />
    
    <!-- World Link-->
    <link name="world"></link>

    <!-- base_joint type float-->

    <joint name="chassis_joint" type="floating">
        <origin xyz="0 0 0.484" rpy = "0 0 0"/>
        <parent link="world"/>
        <child link="chassis_link"/>
    </joint>

    <link name="chassis_link">
        <visual>
            <origin xyz = "0 0 $box_off_z" rpy = "0 0 0"/>
            <geometry>
                <box size="box_x box_y box_z" />
            </geometry>
            <material name = "blue" />
            <collision>
                <origin xyz="0 0 0" rpy="0 0 0" />
                <geometry>
                    <box size="box_x box_y box_z" />
                </geometry>
            </collision>
        <xacro:inertial_box mass="${box_m}" x="${box_x}" y="${box_y}" y="${box_z}">
            <origin xyz="0 0 0" rpy="0 0 0" />
        </xacro:inertial_box>
    

